<?xml version="1.0"?>
<robot name="model1" xmlns:xacro="http://www.ros.org/wiki/xacro">
 <xacro:include filename="$(find robot_description)/urdf/robot_gazebo.xacro"/>
 
<!--<link name="base_footprint">
     <visual>
     <geometry>
       <box size="0.001 0.001 0.001" />
     </geometry>
       <origin xyz="0 0 0" rpy="0 0 0" />
     </visual>
    <inertial>
      <mass value="0.0001" />
      <origin xyz="0 0 0" />
      <inertia ixx="0.0001" ixy="0.0" ixz="0.0"
          iyy="0.0001" iyz="0.0" 
          izz="0.0001" />
    </inertial>
    </link>-->
  
<link name="base_link">
        <visual>
          <geometry>
            <cylinder length="0.005" radius="0.17"/>
          </geometry>
         <material name="light_grey">
           <color rgba="0.7 0.7 0.7 1.0"/>
         </material>
            <origin rpy="0 0 0" xyz="0 0 0.0775"/>
        </visual>
       <collision>
      <geometry>
       <cylinder length="0.005" radius="0.17"/>
      </geometry>
      <origin  rpy="0 0 0" xyz="0 0 0.0775" />
      </collision>      
      <inertial>
       <mass value="2.4"/> <!-- 2.4/2.6 kg for small/big battery pack -->
        <!-- Kobuki's inertia tensor is approximated by a cylinder with homogeneous mass distribution
             More details: http://en.wikipedia.org/wiki/List_of_moment_of_inertia_tensors
             m = 2.4 kg; h = 0.09 m; r = 0.175 m
             ixx = 1/12 * m * (3 * r^2 + h^2)
             iyy = 1/12 * m * (3 * r^2 + h^2)
             izz = 1/2 * m * r^2 
          -->
        <inertia ixx="0.019995" ixy="0.0" ixz="0.0"
                 iyy="0.019995" iyz="0.0" 
                 izz="0.03675" />
      </inertial>
     </link>
<!--<joint name="base_footprint_joint" type="fixed">
    <origin xyz="0 0 0.0775" rpy="0 0 0" />
    <parent link="base_footprint"/>
    <child link="base_link" />
  </joint>--> 
   
    <link name="right_mount">
       <visual>
         <geometry>
           <box size="0.06 0.06 0.06"/>
         </geometry>
         <material name="light_grey">
           <color rgba="0.7 0.7 0.7 1.0"/>
         </material>
         <origin rpy="0 0 0" xyz="0.0 0.0 0.0"/>
       </visual>
      <collision>
      <geometry>
      <box size="0.06 0.06 0.06"/>
      </geometry>
      <origin  rpy="0 0 0" xyz="0.0 0.0 0.0" />
      </collision>      
      <inertial>
        <mass value="0.010" />
        <origin xyz="0 0 0" />
        <inertia ixx="0.001" ixy="0.0" ixz="0.0"
                 iyy="0.001" iyz="0.0" 
                 izz="0.001" />
      </inertial>

     </link>
   
     <joint name="base_to_right_mount" type="fixed">
       <parent link="base_link"/>
       <child link="right_mount"/>
       <origin xyz="-0.06 -0.110 0.0450"/>
   </joint>

  <link name="left_mount">
       <visual>
         <geometry>
           <box size="0.06 0.06 0.06"/>
         </geometry>
         <material name="light_grey">
           <color rgba="0.7 0.7 0.7 1.0"/>
         </material>
         <origin rpy="0 0 0" xyz="0.0 0.0 0.0"/>
       </visual>
     <collision>
      <geometry>
      <box size="0.06 0.06 0.06"/>
      </geometry>
      <origin  rpy="0 0 0" xyz="0.0 0.0 0.0" />
      </collision>      
      <inertial>
        <mass value="0.01" />
        <origin xyz="0 0 0" />
        <inertia ixx="0.001" ixy="0.0" ixz="0.0"
                 iyy="0.001" iyz="0.0" 
                 izz="0.001" />
      </inertial>
     </link>
   
     <joint name="base_to_left_mount" type="fixed">
       <parent link="base_link"/>
       <child link="left_mount"/>
       <origin xyz="-0.06 0.110 0.0450"/>
   </joint>

 <link name="right_wheel">
       <visual>
         <geometry>
           <cylinder length="0.02" radius="0.035"/>
         </geometry>
         <material name="black">
           <color rgba="0 0 0 1.0"/>
         </material>
         <origin rpy="0 1.5707 1.5707 " xyz="0.0 0.0 0.0"/>
       </visual>
 <collision>
      <geometry>
      <cylinder length="0.02" radius="0.035" />
      </geometry>
      <origin  rpy="0 1.5707 1.5707" xyz="0.0 0.0 0.0" />
      </collision>      
      <inertial>
        <mass value="0.010" />
        <origin xyz="0 0 0" />
        <inertia ixx="0.001" ixy="0.0" ixz="0.0"
                 iyy="0.001" iyz="0.0" 
                 izz="0.001" />
      </inertial>
       </link>
   
     <joint name="base_to_right_wheel" type="continuous">
       <parent link="right_mount"/>
       <child link="right_wheel"/>
       <axis xyz="0 1 0"/>
       <origin rpy="0 0 0" xyz="0.0 -0.045 -0.01"/>
   </joint>
 

   <link name="left_wheel">
       <visual>
         <geometry>
           <cylinder length="0.02" radius="0.035"/>
         </geometry>
         <material name="black">
           <color rgba="0 0 0 1"/>
         </material>
         <origin rpy="0 1.5707 1.5707 " xyz="0.0 0.0 0.0"/>
       </visual>
       <collision>
      <geometry>
      <cylinder length="0.02" radius="0.035" />
      </geometry>
      <origin  rpy="0 1.5707 1.5707" xyz="0.0 0.0 0.0" />
      </collision>      
      <inertial>
        <mass value="0.010" />
        <origin xyz="0 1 0" />
        <inertia ixx="0.001" ixy="0.0" ixz="0.0"
                 iyy="0.001" iyz="0.0" 
                 izz="0.001" />
      </inertial>

     </link>
   
     <joint name="base_to_left_wheel" type="continuous">
       <parent link="left_mount"/>
       <child link="left_wheel"/>
       <axis xyz="0 1 0"/>
       <origin rpy="0 0 0" xyz="0.0 0.045 -0.01"/>
   </joint>
 
     <link name="caster_front_link">
     <visual>
      <origin xyz="0 0 0" rpy="1.570796327 0 0" />
      <geometry>
	<sphere radius="0.040" />
      </geometry>
      <material name="black">
          <color rgba="0 0 0 1.0"/>
      </material>
    </visual>  
 <collision>
        <geometry>

	<sphere radius="0.040" />

        </geometry>
      <origin xyz="0 0 0" rpy="1.570796327 0 0" />
      </collision>      
      <inertial>
        <mass value="0.010" />
        <origin xyz="0 0 0" />
        <inertia ixx="0.001" ixy="0.0" ixz="0.0"
                 iyy="0.001" iyz="0.0" 
                 izz="0.001" />
      </inertial>
    </link>



 <joint name="caster_front_joint" type="fixed">
      <parent link="base_link"/>
      <child link="caster_front_link"/>
      <origin xyz="0.13 0 0.040" rpy="-1.570796327 0 0"/>
    </joint>
 
 <link name="tier_link">
        <visual>
          <geometry>
            <cylinder length="0.0915" radius="0.17"/>
          </geometry>
         <material name="light_grey">
           <color rgba="0.7 0.7 0.7 1.0"/>
         </material>
            <origin rpy="0 0 0" xyz="0 0 0"/>
        </visual>
       <collision>
      <geometry>
       <cylinder length="0.005" radius="0.17"/>
      </geometry>
      <origin  rpy="0 0 0" xyz="0 0 0.0" />
      </collision>      
      <inertial>
        <mass value="0.010" />
        <origin xyz="0 0 0" />
        <inertia ixx="0.001" ixy="0.0" ixz="0.0"
                 iyy="0.001" iyz="0.0" 
                 izz="0.001" />
      </inertial>
     </link>
<joint name="tier_base_joint" type="fixed">
    <origin xyz="0 0 0.12575" rpy="0 0 0" /><!--0.04825-->
    <parent link="base_link"/>
    <child link="tier_link" />
  </joint>--> 
   
 <!-- Hokuyo Laser -->
  <link name="laser">
    <collision>
      <origin xyz="0 0 0" rpy="0 0 0"/>
      <geometry>
    <box size="0.1 0.1 0.1"/>
      </geometry>
    </collision>

    <visual>
      <origin xyz="0 0 0" rpy="0 0 0"/>
      <geometry>
        <mesh filename="package://robot_description/meshes/hokuyo.dae"/>
      </geometry>
    </visual>

    <inertial>
      <mass value="1e-5" />
      <origin xyz="0 0 0" rpy="0 0 0"/>
      <inertia ixx="1e-6" ixy="0" ixz="0" iyy="1e-6" iyz="0" izz="1e-6" />
    </inertial>
  </link>

<joint name="laser_joint" type="fixed">
    <!--<axis xyz="0 1 0" />-->
    <origin xyz="0 0 0.1965" rpy="0 0 3.14"/>
    <parent link="base_link"/>
    <child link="laser"/>
  </joint>

<link name="imu_link">
     <visual>
     <geometry>
       <box size="0.026 0.015 0.001" />
     </geometry>
       <origin xyz="0 0 0" rpy="0 0 0" />
     </visual>
    <inertial>
      <mass value="0.0001" />
      <origin xyz="0 0 0" />
      <inertia ixx="0.0001" ixy="0.0" ixz="0.0"
          iyy="0.0001" iyz="0.0" 
          izz="0.0001" />
    </inertial>
    </link>
  <joint name="base_to_imu_link" type="fixed">
       <parent link="base_link"/>
       <child link="imu_link"/>
       <origin xyz="0.13 -0.03 0.0775"/>
   </joint>


</robot>
